Workbook

Sheet GRAFICOS
C2: GRAFICOS STOCK MATERIA PRIMA OCTUBRE 2024
C4: 3-Polipropileno COPOLIMERO manija COD:2630PC | J4: 7-Acetal (AMCEL KP20) M90 | Q4: 15-Santoprene 64 COD:101-64 | X4: 19- PLASTOMER | AF4: 23- Master Gris
C5: MAXIMO | D5: 5000 | J5: MAXIMO | K5: =STOCK!#REF! -> #REF! | Q5: MAXIMO | R5: =STOCK!#REF! -> #REF! | X5: MAXIMO | Y5: =STOCK!K9 -> 5000 | AF5: MAXIMO | AG5: =STOCK!#REF! -> #REF!
C6: Litros consumidos | D6: =STOCK!#REF!-STOCK!#REF! -> #REF! | J6: Litros consumidos | K6: =STOCK!#REF!-STOCK!#REF! -> #REF! | Q6: Litros consumidos | R6: =STOCK!#REF!-STOCK!#REF! -> #REF! | X6: Litros consumidos | Y6: =STOCK!K9-STOCK!F9 -> 4625 | AF6: Litros consumidos | AG6: =STOCK!#REF!-STOCK!#REF! -> #REF!
C7: EN STOCK | D7: =STOCK!#REF!+STOCK!#REF! -> #REF! | J7: EN STOCK | K7: =STOCK!#REF! -> #REF! | Q7: EN STOCK | R7: =STOCK!F13 -> 87.555 | X7: EN STOCK | Y7: =STOCK!F9 -> 375 | AF7: EN STOCK | AG7: =STOCK!#REF! -> #REF!
C8: Stock minimo | D8: =STOCK!#REF! -> #REF! | J8: Stock minimo | K8: =STOCK!#REF! -> #REF! | Q8: Stock minimo | R8: =STOCK!#REF! -> #REF! | X8: Stock minimo | Y8: =STOCK!J9 -> 3000 | AF8: Stock minimo | AG8: =STOCK!#REF! -> #REF!
C9: Tapa | D9: 0.1 | J9: Tapa | K9: 0.1 | Q9: Tapa | R9: 0.1 | X9: Tapa | Y9: 0.1 | AF9: Tapa | AG9: 0.1
C10: LLeno | D10: =+(D5-D6)/D5 -> #REF! | J10: LLeno | K10: =+(K5-K6)/K5 -> #REF! | Q10: LLeno | R10: =+(R5-R6)/R5 -> #REF! | X10: LLeno | Y10: =+(Y5-Y6)/Y5 -> 0.075 | AF10: LLeno | AG10: =+(AG5-AG6)/AG5 -> #REF!
C11: Vacio | D11: =1-D10 -> #REF! | J11: Vacio | K11: =1-K10 -> #REF! | Q11: Vacio | R11: =1-R10 -> #REF! | X11: Vacio | Y11: =1-Y10 -> 0.925 | AF11: Vacio | AG11: =1-AG10 -> #REF!
C12: Tapa | D12: 0.1 | J12: Tapa | K12: 0.1 | Q12: Tapa | R12: 0.1 | X12: Tapa | Y12: 0.1 | AF12: Tapa | AG12: 0.1
C14: 4-Polipropileno homopolimero 1102K | J14: 8-Acetal (DURACOM 15M6770) M270 | Q14: 16- Santoprene 80 - COD:101-80 | X14: 20- A.B.C VIRGEN | AF14: 24- Master negro 951
C15: MAXIMO | D15: 25000 | J15: MAXIMO | K15: =STOCK!#REF! -> #REF! | Q15: MAXIMO | R15: =STOCK!#REF! -> #REF! | X15: MAXIMO | Y15: =STOCK!#REF! -> #REF! | AF15: MAXIMO | AG15: =STOCK!K13 -> 75
C16: Litros consumidos | D16: =STOCK!#REF!-STOCK!#REF! -> #REF! | J16: Litros consumidos | K16: =STOCK!#REF!-STOCK!#REF! -> #REF! | Q16: Litros consumidos | R16: =STOCK!#REF!-STOCK!#REF! -> #REF! | X16: Litros consumidos | Y16: =STOCK!#REF!-STOCK!#REF! -> #REF! | AF16: Litros consumidos | AG16: =STOCK!K13-STOCK!F13 -> -12.555
C17: EN STOCK | D17: =GRAFICOS!D15-GRAFICOS!D16 -> #REF! | J17: EN STOCK | K17: =STOCK!#REF! -> #REF! | Q17: EN STOCK | R17: =STOCK!#REF! -> #REF! | X17: EN STOCK | Y17: =STOCK!#REF! -> #REF! | AF17: EN STOCK | AG17: =STOCK!F13 -> 87.555
C18: Stock minimo | D18: 5000 | J18: Stock minimo | K18: =STOCK!#REF! -> #REF! | Q18: Stock minimo | R18: =STOCK!#REF! -> #REF! | X18: Stock minimo | Y18: =STOCK!#REF! -> #REF! | AF18: Stock minimo | AG18: =STOCK!J13 -> 25
C19: Tapa | D19: 0.1 | J19: Tapa | K19: 0.1 | Q19: Tapa | R19: 0.1 | X19: Tapa | Y19: 0.1 | AF19: Tapa | AG19: 0.1
C20: LLeno | D20: =+(D15-D16)/D15 -> #REF! | J20: LLeno | K20: =+(K15-K16)/K15 -> #REF! | Q20: LLeno | R20: =+(R15-R16)/R15 -> #REF! | X20: LLeno | Y20: =+(Y15-Y16)/Y15 -> #REF! | AF20: LLeno | AG20: =+(AG15-AG16)/AG15 -> 1.1674
C21: Vacio | D21: =1-D20 -> #REF! | J21: Vacio | K21: =1-K20 -> #REF! | Q21: Vacio | R21: =1-R20 -> #REF! | X21: Vacio | Y21: =1-Y20 -> #REF! | AF21: Vacio | AG21: =1-AG20 -> -0.1674
C22: Tapa | D22: 0.1 | J22: Tapa | K22: 0.1 | Q22: Tapa | R22: 0.1 | X22: Tapa | Y22: 0.1 | AF22: Tapa | AG22: 0.1
C24: 5-Poliprolipeno C/ carga ALL816-1 | J24: 9-ACETAL NATURAL KOCETAL | Q24: 17- Santoprene 64 COD:201-64 Diferente color | X24: 21- Master Azul | AF24: 28- Acetal KO GF 705 natural (ACETAL CON 25% FIBRA FLUENCIA 705 POM )
C25: MAXIMO | D25: 1500 | J25: MAXIMO | K25: =STOCK!#REF! -> #REF! | Q25: MAXIMO | R25: =STOCK!#REF! -> #REF! | X25: MAXIMO | Y25: =STOCK!K12 -> 75 | AF25: MAXIMO | AG25: =STOCK!#REF! -> #REF!
C26: Litros consumidos | D26: =STOCK!#REF!-STOCK!#REF! -> #REF! | J26: Litros consumidos | K26: =STOCK!#REF!-STOCK!#REF! -> #REF! | Q26: Litros consumidos | R26: =STOCK!#REF!-STOCK!#REF! -> #REF! | X26: Litros consumidos | Y26: =STOCK!K12-STOCK!F12 -> 52.62 | AF26: Litros consumidos | AG26: =STOCK!#REF!-STOCK!#REF! -> #REF!
C27: EN STOCK | D27: =D25-D26 -> #REF! | J27: EN STOCK | K27: =STOCK!#REF! -> #REF! | Q27: EN STOCK | R27: =STOCK!#REF! -> #REF! | X27: EN STOCK | Y27: =STOCK!F12 -> 22.38 | AF27: EN STOCK | AG27: =STOCK!F13 -> 87.555
C28: Stock minimo | D28: 500 | J28: Stock minimo | K28: =STOCK!#REF! -> #REF! | Q28: Stock minimo | R28: =STOCK!#REF! -> #REF! | X28: Stock minimo | Y28: =STOCK!J12 -> 25 | AF28: Stock minimo | AG28: =STOCK!#REF! -> #REF!
C29: Tapa | D29: 0.1 | J29: Tapa | K29: 0.1 | Q29: Tapa | R29: 0.1 | X29: Tapa | Y29: 0.1 | AF29: Tapa | AG29: 0.1
C30: LLeno | D30: =+(D25-D26)/D25 -> #REF! | J30: LLeno | K30: =+(K25-K26)/K25 -> #REF! | Q30: LLeno | R30: =+(R25-R26)/R25 -> #REF! | X30: LLeno | Y30: =+(Y25-Y26)/Y25 -> 0.2984 | AF30: LLeno | AG30: =+(AG25-AG26)/AG25 -> #REF!
C31: Vacio | D31: =1-D30 -> #REF! | J31: Vacio | K31: =1-K30 -> #REF! | Q31: Vacio | R31: =1-R30 -> #REF! | X31: Vacio | Y31: =1-Y30 -> 0.7016 | AF31: Vacio | AG31: =1-AG30 -> #REF!
C32: Tapa | D32: 0.1 | J32: Tapa | K32: 0.1 | Q32: Tapa | R32: 0.1 | X32: Tapa | Y32: 0.1 | AF32: Tapa | AG32: 0.1
C34: 6-Polietileno COD:8818 MEDIA | J34: 14-Santoprene 80 COD:201-80 | Q34: 18-Prinz PVC COD: 55-021-NRG001 | X34: 22-Master Amarillo
C35: MAXIMO | D35: =STOCK!K8 -> 200 | J35: MAXIMO | K35: =STOCK!#REF! -> #REF! | Q35: MAXIMO | R35: =STOCK!#REF! -> #REF! | X35: MAXIMO | Y35: =STOCK!#REF! -> #REF!
C36: Litros consumidos | D36: =STOCK!K8-STOCK!F8 -> 200 | J36: Litros consumidos | K36: =STOCK!#REF!-STOCK!#REF! -> #REF! | Q36: Litros consumidos | R36: =STOCK!#REF!-STOCK!#REF! -> #REF! | X36: Litros consumidos | Y36: =STOCK!#REF!-STOCK!#REF! -> #REF!
C37: EN STOCK | D37: =STOCK!F8 -> 0 | J37: EN STOCK | K37: =STOCK!#REF! -> #REF! | Q37: EN STOCK | R37: =STOCK!#REF! -> #REF! | X37: EN STOCK | Y37: =STOCK!#REF! -> #REF!
C38: Stock minimo | D38: =STOCK!J8 -> 100 | J38: Stock minimo | K38: =STOCK!#REF! -> #REF! | Q38: Stock minimo | R38: =STOCK!#REF! -> #REF! | X38: Stock minimo | Y38: =STOCK!#REF! -> #REF!
C39: Tapa | D39: 0.1 | J39: Tapa | K39: 0.1 | Q39: Tapa | R39: 0.1 | X39: Tapa | Y39: 0.1
C40: LLeno | D40: =+(D35-D36)/D35 -> 0 | J40: LLeno | K40: =+(K35-K36)/K35 -> #REF! | Q40: LLeno | R40: =+(R35-R36)/R35 -> #REF! | X40: LLeno | Y40: =+(Y35-Y36)/Y35 -> #REF!
C41: Vacio | D41: =1-D40 -> 1 | J41: Vacio | K41: =1-K40 -> #REF! | Q41: Vacio | R41: =1-R40 -> #REF! | X41: Vacio | Y41: =1-Y40 -> #REF!
C42: Tapa | D42: 0.1 | J42: Tapa | K42: 0.1 | Q42: Tapa | R42: 0.1 | X42: Tapa | Y42: 0.1

Sheet STOCK
A3: Stock materia prima agosto 2026
A5: CODIGO INTERNO | B5: MATERIAL VIRGEN | C5: STOCK AL 04/08/2026 | D5: INGRESOS | E5: EGRESOS | F5: STOCK A FECHA 11/08/2026 | G5: FISICO AL 07/08/2026 | H5: DIFERENCIA DE STOCK | I5: AGRGADOS | J5: STOCK MINIMO | K5: STOCK MAXIMO | L5: COMPRAS EN PROCESA | M5: ESTADO | N5: comentarios
A6: 3 | B6: 3-Polipropileno COPOLIMERO COD:2630PC | C6: 50 | D6: =INGRESO!X6 -> 4000 | E6: =EGRESO!X6 -> 0 | F6: =(C6+D6)-E6 -> 4050 | H6: =F6-G6 -> 4050 | J6: 3000 | K6: 5000
A7: 4 | B7: 04- polipropileno homopolimero | C7: 0 | D7: =INGRESO!X7 -> 0 | E7: =EGRESO!X7 -> 0 | F7: =(C7+D7)-E7 -> 0 | H7: =F7-G7 -> 0 | J7: 100 | K7: 200
A8: 6 | B8: 6-Polietileno COD:8818 MEDIA | C8: 0 | D8: =INGRESO!X8 -> 0 | E8: =EGRESO!X8 -> 0 | F8: =(C8+D8)-E8 -> 0 | H8: =F8-G8 -> 0 | J8: 100 | K8: 200
A9: 19 | B9: 19- PLASTOMER | C9: 375 | D9: =INGRESO!X9 -> 0 | E9: =EGRESO!X9 -> 0 | F9: =(C9+D9)-E9 -> 375 | H9: =F9-G9 -> 375 | J9: 3000 | K9: 5000
A10: 31 | B10: 31-COPOLIMERO 2240 P | C10: 6300 | D10: =INGRESO!X10 -> 0 | E10: =EGRESO!X10 -> 3300 | F10: =(C10+D10)-E10 -> 3000 | H10: =F10-G10 -> 3000 | J10: 3000 | K10: 5000
A11: 38 | B11: 38-compuesto PE AD SN | C11: 0 | D11: =INGRESO!X11 -> 0 | E11: =EGRESO!X11 -> 0 | F11: =(C11+D11)-E11 -> 0 | H11: =F11-G11 -> 0 | N11: se utiliza para limpieza en evaluacion de cambio
A12: 21 | B12: 21-Master Azul | C12: 22.38 | D12: =INGRESO!X12 -> 0 | E12: =EGRESO!X12 -> 0 | F12: =(C12+D12)-E12 -> 22.38 | H12: =F12-G12 -> 22.38 | J12: 25 | K12: 75
A13: 24 | B13: 24-Master negro 951 | C13: 37.555 | D13: =INGRESO!X13 -> 50 | E13: =EGRESO!X13 -> 0 | F13: =(C13+D13)-E13 -> 87.555 | H13: =F13-G13 -> 87.555 | J13: 25 | K13: 75
A14: B 1 | B14: B1-Master Gris Oscuro 105808 | C14: 8.743 | D14: =INGRESO!X14 -> 35.827 | E14: =EGRESO!X14 -> 11.4 | F14: =(C14+D14)-E14 -> 33.17 | H14: =F14-G14 -> 33.17 | J14: 10 | K14: 20
A15: B 3 | B15: B3-Master Blanco | C15: 0 | D15: =INGRESO!X15 -> 0 | E15: =EGRESO!X15 -> 0 | F15: =(C15+D15)-E15 -> 0 | H15: =F15-G15 -> 0 | J15: 3.5 | K15: 5
A16: B 4 | B16: B4-Master Azul oscuro 100954 | C16: 4.459 | D16: =INGRESO!X16 -> 0 | E16: =EGRESO!X16 -> 0 | F16: =(C16+D16)-E16 -> 4.459 | H16: =F16-G16 -> 4.459 | J16: 3.5 | K16: 5
A17: B 5 | B17: B5- Master Amarillo 114247 | C17: 2.7 | D17: =INGRESO!X17 -> 0 | E17: =EGRESO!X17 -> 0 | F17: =(C17+D17)-E17 -> 2.7 | H17: =F17-G17 -> 2.7 | J17: Se reemplaza con A5 | K17: 0
A18: A5 | B18: A5- Master Amarillo 7228 | C18: 0 | D18: =INGRESO!X18 -> 5 | E18: =EGRESO!X18 -> 0 | F18: =(C18+D18)-E18 -> 5 | H18: =F18-G18 -> 5 | J18: 3.5 | K18: 5 | L18: 5
A19: B 6 | B19: B6- Master Verde 113227 | C19: 2.496 | D19: =INGRESO!X19 -> 0 | E19: =EGRESO!X19 -> 0 | F19: =(C19+D19)-E19 -> 2.496 | H19: =F19-G19 -> 2.496 | J19: 3.5 | K19: 5
A20: B 7 | B20: B7-Master Rojo 100319 | C20: 1.896 | D20: =INGRESO!X20 -> 5 | E20: =EGRESO!X20 -> 0 | F20: =(C20+D20)-E20 -> 6.896 | H20: =F20-G20 -> 6.896 | J20: 3.5 | K20: 5
A21: B10 | B21: B10-Master Gris Oscuro nor 108900 (gris claro catalogo) | C21: 8.45 | D21: =INGRESO!X21 -> 0 | E21: =EGRESO!X21 -> 0 | F21: =(C21+D21)-E21 -> 8.45 | H21: =F21-G21 -> 8.45 | J21: 3.5 | K21: 5
A22: B11 | B22: B11-Master celeste 112228 | C22: 2.76 | D22: =INGRESO!X22 -> 0 | E22: =EGRESO!X22 -> 2.7 | F22: =(C22+D22)-E22 -> 0.06 | H22: =F22-G22 -> 0.06 | J22: 3.5 | K22: 5
A23: A9 | B23: A9-Master naranja 7363 | C23: 4.209 | D23: =INGRESO!X23 -> 0 | E23: =EGRESO!X23 -> 0 | F23: =(C23+D23)-E23 -> 4.209 | H23: =F23-G23 -> 4.209 | J23: 3.5 | K23: 5
A24: A14 | B24: A14- Master Yute 4101 | C24: 0.198 | D24: =INGRESO!X24 -> 5 | E24: =EGRESO!X24 -> 0 | F24: =(C24+D24)-E24 -> 5.198 | H24: =F24-G24 -> 5.198 | J24: 3.5 | K24: 5 | L24: 5
A25: A3 | B25: A3-MASTER BLANCO 7500 | C25: 2.802 | D25: =INGRESO!X25 -> 0 | E25: =EGRESO!X25 -> 0 | F25: =(C25+D25)-E25 -> 2.802 | H25: =F25-G25 -> 2.802 | J25: 3.5 | K25: 5
B26: Materiales de muestra o alternativos | C26: STOCK AL 04/08/2026 | D26: INGRESOS | E26: EGRESOS | F26: STOCK A FECHA 11/08/2026 | G26: FISICO AL 07/08/2026 | H26: DIFERENCIA DE STOCK | I26: AGRGADOS | J26: STOCK MINIMO | K26: STOCK MAXIMO | L26: COMPRAS EN PROCESA | M26: ESTADO | N26: comentarios
A27: P 1 | B27: P1-Master Gris Oscuro 991700 | C27: 1.275 | D27: =INGRESO!X27 -> 0 | E27: =EGRESO!X27 -> 0 | F27: =(C27+D27)-E27 -> 1.275 | H27: =F27-G27 -> 1.275
A28: P 2 | B28: P2 Master Gris Claro 991010 | C28: 0.335 | D28: =INGRESO!X28 -> 0 | E28: =EGRESO!X28 -> 0 | F28: =(C28+D28)-E28 -> 0.335 | H28: =F28-G28 -> 0.335
A29: P 3 | B29: P3-Master Blanco | C29: 0 | D29: =INGRESO!X29 -> 0 | E29: =EGRESO!X29 -> 0 | F29: =(C29+D29)-E29 -> 0 | H29: =F29-G29 -> 0
A30: P 4 | B30: P4-Master Azul oscuro 961515 | C30: 1 | D30: =INGRESO!X30 -> 0 | E30: =EGRESO!X30 -> 0 | F30: =(C30+D30)-E30 -> 1 | H30: =F30-G30 -> 1
A31: P 5 | B31: P5- Master Amarillo1303342 | C31: 0.75 | D31: =INGRESO!X31 -> 0 | E31: =EGRESO!X31 -> 0 | F31: =(C31+D31)-E31 -> 0.75 | H31: =F31-G31 -> 0.75
A32: P 6 | B32: P6- Master Verde 1704673 | C32: 0.68 | D32: =INGRESO!X32 -> 0 | E32: =EGRESO!X32 -> 0 | F32: =(C32+D32)-E32 -> 0.68 | H32: =F32-G32 -> 0.68
A33: P 7 | B33: P7-Master Rojo1501925 | C33: 1.075 | D33: =INGRESO!X33 -> 0 | E33: =EGRESO!X33 -> 0 | F33: =(C33+D33)-E33 -> 1.075 | H33: =F33-G33 -> 1.075
A34: P 8 | B34: P8-Master Azul claro am 068 | C34: 0.148 | D34: =INGRESO!X34 -> 0 | E34: =EGRESO!X34 -> 0 | F34: =(C34+D34)-E34 -> 0.148 | H34: =F34-G34 -> 0.148
A35: P 9 | B35: P9-Master Naranja 1100406 | C35: 0.62 | D35: =INGRESO!X35 -> 0 | E35: =EGRESO!X35 -> 0 | F35: =(C35+D35)-E35 -> 0.62 | H35: =F35-G35 -> 0.62
A36: p10 | B36: P10-Master negro991333 | C36: 1.635 | D36: =INGRESO!X36 -> 0 | E36: =EGRESO!X36 -> 0 | F36: =(C36+D36)-E36 -> 1.635 | H36: =F36-G36 -> 1.635
A37: p11 | B37: P11-Master celeste 961150 | C37: 0.74 | D37: =INGRESO!X37 -> 0 | E37: =EGRESO!X37 -> 0 | F37: =(C37+D37)-E37 -> 0.74 | H37: =F37-G37 -> 0.74
A38: P15 | B38: P15-master perlado 020 | C38: 0.172 | D38: =INGRESO!X38 -> 0 | E38: =EGRESO!X38 -> 0 | F38: =(C38+D38)-E38 -> 0.172 | H38: =F38-G38 -> 0.172
A39: A4 | B39: A4- Master Azul 3351 | C39: 4.871 | D39: =INGRESO!X39 -> 25.382 | E39: =EGRESO!X39 -> 15.75 | F39: =(C39+D39)-E39 -> 14.503 | H39: =F39-G39 -> 14.503 | L39: 25
A40: A6 | B40: A6-Master Verde 4170 | C40: 3.558 | D40: =INGRESO!X40 -> 0 | E40: =EGRESO!X40 -> 0 | F40: =(C40+D40)-E40 -> 3.558 | H40: =F40-G40 -> 3.558
A41: A12 | B41: A12-MASTER VIOLETA 3353 | C41: 0.844 | D41: =INGRESO!X41 -> 0 | E41: =EGRESO!X41 -> 0 | F41: =(C41+D41)-E41 -> 0.844 | H41: =F41-G41 -> 0.844
A42: A13 | B42: A13-MASTER OBISPO 3119 | C42: 1.815 | D42: =INGRESO!X42 -> 0 | E42: =EGRESO!X42 -> 0.15 | F42: =(C42+D42)-E42 -> 1.665 | H42: =F42-G42 -> 1.665
A43: B16 | B43: B6-fucsia | C43: 0.3 | D43: =INGRESO!X43 -> 0 | E43: =EGRESO!X43 -> 0 | F43: =(C43+D43)-E43 -> 0.3 | H43: =F43-G43 -> 0.3
...

Sheet INGRESO
B2: Stock materia prima agosto 2026
D3: Transferencias de CP a NEXA se marcan con
B4: INGRESOS DE MATERIA PRIMA
B5: CODIGO INTERNO | C5: MATERIAL VIRGEN | D5: 4 | E5: 5 | F5: 6 | G5: 7 | H5: 10 | I5: 11 | J5: 12 | K5: 13 | L5: 14 | M5: 17F | N5: 19 | O5: 19 | P5: 20 | Q5: 21 | R5: 24 | S5: 25 | T5: 26 | U5: 27 | V5: 28 | W5: 31 | X5: Total | Y5: Observaciones
B6: 3 | C6: 3-Polipropileno COPOLIMERO COD:2630PC | E6: 4000 | X6: =SUM(D6:W6) -> 4000
B7: 4 | C7: 04- polipropileno homopolimero | X7: =SUM(D7:W7) -> 0
B8: 6 | C8: 6-Polietileno COD:8818 MEDIA | X8: =SUM(D8:W8) -> 0
B9: 19 | C9: 19- PLASTOMER | X9: =SUM(D9:W9) -> 0
B10: 31 | C10: 31-COPOLIMERO 2240 P | X10: =SUM(D10:W10) -> 0
B11: 38 | C11: 38-compuesto PE AD SN | X11: =SUM(D11:W11) -> 0
B12: 21 | C12: 21-Master Azul | X12: =SUM(D12:W12) -> 0
B13: 24 | C13: 24-Master negro 951 | E13: 50 | X13: =SUM(D13:W13) -> 50
B14: B 1 | C14: B1-Master Gris Oscuro 105808 | E14: 35 | F14: 0.827 | X14: =SUM(D14:W14) -> 35.827 | Y14: diferencia de peso po armada d bolsitas
B15: B 3 | C15: B3-Master Blanco | X15: =SUM(D15:W15) -> 0
B16: B 4 | C16: B4-Master Azul oscuro 100954 | X16: =SUM(D16:W16) -> 0
B17: B 5 | C17: B5- Master Amarillo 114247 | X17: =SUM(D17:W17) -> 0
B18: A5 | C18: A5- Master Amarillo 7228 | H18: 5 | X18: =SUM(D18:W18) -> 5
B19: B 6 | C19: B6- Master Verde 113227 | X19: =SUM(D19:W19) -> 0
B20: B 7 | C20: B7-Master Rojo 100319 | E20: 5 | X20: =SUM(D20:W20) -> 5
B21: B10 | C21: B10-Master Gris Oscuro nor 108900 (gris claro catalogo) | X21: =SUM(D21:W21) -> 0
B22: B11 | C22: B11-Master celeste 112228 | X22: =SUM(D22:W22) -> 0
B23: A9 | C23: A9-Master naranja 7363 | X23: =SUM(D23:W23) -> 0
B24: A14 | C24: A14- Master Yute 4101 | H24: 5 | X24: =SUM(D24:W24) -> 5
B25: A3 | C25: A3-MASTER BLANCO 7500 | X25: =SUM(D25:W25) -> 0
B26: CODIGO INTERNO | C26: Materiales de muestra o alternativos | D26: 4 | E26: 5 | F26: 6 | G26: 7 | H26: 10 | I26: 11 | J26: 12 | K26: 13 | L26: 14 | M26: 17F | N26: 19 | O26: 19 | P26: 20 | Q26: 21 | R26: 24 | S26: 25 | T26: 26 | U26: 27 | V26: 28 | W26: 31 | X26: Total
B27: P 1 | C27: P1-Master Gris Oscuro 991700 | X27: =SUM(D27:W27) -> 0
B28: P 2 | C28: P2 Master Gris Claro 991010 | X28: =SUM(D28:W28) -> 0
B29: P 3 | C29: P3-Master Blanco | X29: =SUM(D29:W29) -> 0
B30: P 4 | C30: P4-Master Azul oscuro 961515 | X30: =SUM(D30:W30) -> 0
B31: P 5 | C31: P5- Master Amarillo1303342 | X31: =SUM(D31:W31) -> 0
B32: P 6 | C32: P6- Master Verde 1704673 | X32: =SUM(D32:W32) -> 0
B33: P 7 | C33: P7-Master Rojo1501925 | X33: =SUM(D33:W33) -> 0
B34: P 8 | C34: P8-Master Azul claro am 068 | X34: =SUM(D34:W34) -> 0
B35: P 9 | C35: P9-Master Naranja 1100406 | X35: =SUM(D35:W35) -> 0
B36: p10 | C36: P10-Master negro991333 | X36: =SUM(D36:W36) -> 0
B37: p11 | C37: P11-Master celeste 961150 | X37: =SUM(D37:W37) -> 0
B38: P15 | C38: P15-master perlado 020 | X38: =SUM(D38:W38) -> 0
B39: A4 | C39: A4- Master Azul 3351 | H39: =25+0.382 -> 25.382 | X39: =SUM(D39:W39) -> 25.382
B40: A6 | C40: A6-Master Verde 4170 | X40: =SUM(D40:W40) -> 0
B41: A12 | C41: A12-MASTER VIOLETA 3353 | X41: =SUM(D41:W41) -> 0
...

Sheet BOLSONES
B13: 115-Molienda Polipropieleno de primera
B14: lote | C14: fecha | D14: canasto N° | E14: Peso inicial | F14: Entradas | G14: Salidas | H14: sub total | I14: sub totales | J14: TOTAL | K14: estado
B15: 1 | J15: 257.6 | K15: cerrado
B16: 2 | J16: 488.305 | K16: cerrado
B17: 3 | J17: 370.4 | K17: cerrado
B18: 4 | J18: 468 | K18: cerrado
B19: 5 | J19: 746.2 | K19: cerrado
B20: 6 | J20: 314 | K20: cerrado
B21: 7 | J21: 221 | K21: cerrado
B22: 8 | J22: 297.84 | K22: cerrado
B23: 9 | J23: 316 | K23: cerrado
B24: 10 | E24: 142.355 | J24: =I24 -> 0
C25: 45834 | D25: 27
C26: 45834 | D26: 26.245
C27: 45834 | D27: 27.4
C28: 45834 | D28: 27.92
C33: subtotales | D33: =SUM(D25:D32) -> 108.565 | E33: =SUM(E24:E32) -> 142.355 | G33: =SUM(G24:G32) -> 0 | J33: =SUM(J15:J32) -> 3479.345
H34: total | J34: =J33+D33+E33-G33 -> 3730.265
B38: Bolson
B39: 124- Molienda Acetal de primera
B40: Bolson N°1 | E40: fecha | F40: Peso inicial | G40: Entradas | H40: Salidas | I40: total | J40: fecha | K40: bolsa | L40: canasto
B41: BOLSON 8 | E41: 45817 | F41: 569.4 | I41: =(F41+G41)-H41 -> 569.4
I42: =(F42+G42)-H42 -> 0
I43: =(F43+G43)-H43 -> 0
I44: =(F44+G44)-H44 -> 0
I45: =(F45+G45)-H45 -> 0
I46: =(F46+G46)-H46 -> 0
I47: =(F47+G47)-H47 -> 0
I48: =(F48+G48)-H48 -> 0
I49: =(F49+G49)-H49 -> 0
I50: =(F50+G50)-H50 -> 0
I51: =(F51+G51)-H51 -> 0
I52: =(F52+G52)-H52 -> 0
I53: =(F53+G53)-H53 -> 0
... I55: =(F55+G55)-H55 -> 0
G56: =SUM(G41:G55) -> 0 | H56: =SUM(H41:H55) -> 0 | I56: =(F56+G56)-H56 -> 0
F57: total | I57: =SUM(I41:I56)+K57+L57 -> 569.4 | K57: =SUM(K41:K56) -> 0 | L57: =SUM(L41:L56) -> 0
B59: Bolson
B60: 5-Poliprolipeno C/ carga ALL 816-1 o 512
B61: Bolson N° | F61: Peso inicial | G61: Entradas | H61: Salidas | I61: total | J61: fecha | K61: bolsa | L61: canasto
...

Sheet EGRESO
B2: 46235 | O2: transferencias de Nexa a CP se marcan con
B4: EGRESOS DE MATERIA PRIMA
B5: CODIGO INTERNO | C5: MATERIAL VIRGEN | D5: 4 | E5: 5 | F5: 6 | G5: 7 | H5: 10 | I5: 11 | J5: 12 | K5: 13 | L5: 14 | M5: 17F | N5: 19 | O5: 19 | P5: 20 | Q5: 21 | R5: 24 | S5: 25 | T5: 26 | U5: 27 | V5: 28 | W5: 31 | X5: Total | Y5: Observaciones
B6: 3 | C6: 3-Polipropileno COPOLIMERO COD:2630PC | X6: =SUM(D6:W6) -> 0
B7: 4 | C7: 04- polipropileno homopolimero | X7: =SUM(D7:W7) -> 0
B8: 6 | C8: 6-Polietileno COD:8818 MEDIA | X8: =SUM(D8:W8) -> 0
B9: 19 | C9: 19- PLASTOMER | X9: =SUM(D9:W9) -> 0
B10: 31 | C10: 31-COPOLIMERO 2240 P | D10: 500 | F10: 300 | G10: 300 | H10: 2200 | X10: =SUM(D10:W10) -> 3300
B11: 38 | C11: 38-compuesto PE AD SN | X11: =SUM(D11:W11) -> 0
B12: 21 | C12: 21-Master Azul | X12: =SUM(D12:W12) -> 0
B13: 24 | C13: 24-Master negro 951 | X13: =SUM(D13:W13) -> 0
B14: B 1 | C14: B1-Master Gris Oscuro 105808 | D14: 7.5 | F14: 3.9 | X14: =SUM(D14:W14) -> 11.4
B15: B 3 | C15: B3-Master Blanco | X15: =SUM(D15:W15) -> 0
B16: B 4 | C16: B4-Master Azul oscuro 100954 | X16: =SUM(D16:W16) -> 0
B17: B 5 | C17: B5- Master Amarillo 114247 | X17: =SUM(D17:W17) -> 0
B18: A5 | C18: A5- Master Amarillo 7228 | X18: =SUM(D18:W18) -> 0
B19: B 6 | C19: B6- Master Verde 113227 | X19: =SUM(D19:W19) -> 0
B20: B 7 | C20: B7-Master Rojo 100319 | X20: =SUM(D20:W20) -> 0
B21: B10 | C21: B10-Master Gris Oscuro nor 108900 (gris claro catalogo) | X21: =SUM(D21:W21) -> 0
B22: B11 | C22: B11-Master celeste 112228 | I22: 2.7 | X22: =SUM(D22:W22) -> 2.7
B23: A9 | C23: A9-Master naranja 7363 | X23: =SUM(D23:W23) -> 0
B24: A14 | C24: A14- Master Yute 4101 | X24: =SUM(D24:W24) -> 0
B25: A3 | C25: A3-MASTER BLANCO 7500 | X25: =SUM(D25:W25) -> 0
B26: CODIGO INTERNO | C26: Materiales de muestra o alternativos | D26: 4 | E26: 5 | F26: 6 | G26: 7 | H26: 10 | I26: 11 | J26: 12 | K26: 13 | L26: 14 | M26: 17F | N26: 19 | O26: 19 | P26: 20 | Q26: 21 | R26: 24 | S26: 25 | T26: 26 | U26: 27 | V26: 28 | W26: 31 | X26: Total
B27: P 1 | C27: P1-Master Gris Oscuro 991700 | X27: =SUM(D27:W27) -> 0
B28: P 2 | C28: P2 Master Gris Claro 991010 | X28: =SUM(D28:W28) -> 0
B29: P 3 | C29: P3-Master Blanco | X29: =SUM(D29:W29) -> 0
B30: P 4 | C30: P4-Master Azul oscuro 961515 | X30: =SUM(D30:W30) -> 0
B31: P 5 | C31: P5- Master Amarillo1303342 | X31: =SUM(D31:W31) -> 0
B32: P 6 | C32: P6- Master Verde 1704673 | X32: =SUM(D32:W32) -> 0
B33: P 7 | C33: P7-Master Rojo1501925 | X33: =SUM(D33:W33) -> 0
B34: P 8 | C34: P8-Master Azul claro am 068 | X34: =SUM(D34:W34) -> 0
B35: P 9 | C35: P9-Master Naranja 1100406 | X35: =SUM(D35:W35) -> 0
B36: p10 | C36: P10-Master negro991333 | X36: =SUM(D36:W36) -> 0
B37: p11 | C37: P11-Master celeste 961150 | X37: =SUM(D37:W37) -> 0
B38: P15 | C38: P15-master perlado 020 | X38: =SUM(D38:W38) -> 0
B39: A4 | C39: A4- Master Azul 3351 | G39: 4.8 | H39: 4.2 | I39: 6.75 | X39: =SUM(D39:W39) -> 15.75
B40: A6 | C40: A6-Master Verde 4170 | X40: =SUM(D40:W40) -> 0
B41: A12 | C41: A12-MASTER VIOLETA 3353 | X41: =SUM(D41:W41) -> 0
B42: A13 | C42: A13-MASTER OBISPO 3119 | D42: 0.15 | X42: =SUM(D42:W42) -> 0.15
...

Sheet MASTER  
B3: B1-Master Gris Oscuro 105808 | I3: SOBRANTE X DIFERENCIA DE BALANSA | K3: 46238
B4: fecha | C4: cantidad armada B | D4: peso bolsa al 21/3/2025 | E4: peso por bolsa | F4: cantidad entregada por día | G4: peso | K4: CUADRO DE MASTERS NORMALIZADOS PARA EL CATALOGO (Proveedor y codigo )
B5: bolsa entera | C5: si | G5: =F5*0.08 -> 0 | H5: =G5*D5 -> 0 | K5: COLORES Y PROVEEDORES ELEJIDOS
B6: bolsa abierta | G6: =F6*0.08 -> 0 | H6: =G6*D6 -> 0 | K6: Negro | L6: BERMA | M6: 24B-Master negro 951
B7: 46240 | C7: 221 | D7: 0.15 | E7: =C7*D7 -> 33.15 | G7: =F7*0.08 -> 0 | H7: =G7*D7 -> 0 | L7: BERMA | M7: B1-Master Gris Oscuro 105808
C8: 1 | D8: 0.02 | E8: =C8*D8 -> 0.02 | G8: =F8*0.15 -> 0 | H8: =G8*D8 -> 0 | L8: BERMA | M8: B10-Master Gris Claro (gris Oscuro nordico 108900)
D9: 0.15 | E9: =C9*D9 -> 0 | G9: =F9*0.15 -> 0 | H9: =G9*D9 -> 0 | L9: ARCOLOR | M9: A3- Master blanco 7500
D10: 0.15 | E10: =C10*D10 -> 0 | G10: =F10*0.15 -> 0 | H10: =G10*D10 -> 0 | L10: BERMA | M10: B11-Master celeste 112228
D11: 0.05 | E11: =C11*D11 -> 0 | G11: =F11*0.15 -> 0 | H11: =G11*D11 -> 0 | L11: BERMA | M11: 21B-Master Azul
D12: 0.15 | E12: =C12*D12 -> 0 | G12: =F12*0.15 -> 0 | H12: =G12*D12 -> 0 | L12: ARCOLOR | M12: A4- Master Azul 3351
D13: 0.15 | E13: =C13*D13 -> 0 | G13: =F13*0.15 -> 0 | H13: =G13*D13 -> 0 | L13: ARCOLOR | M13: A5Master amarillo 7228
D14: 0.15 | E14: =C14*D14 -> 0 | G14: =F14*0.15 -> 0 | H14: =G14*D14 -> 0 | L14: BERMA | M14: B6- Master Verde 113227
D15: 0.15 | E15: =C15*D15 -> 0 | G15: =F15*0.15 -> 0 | H15: =G15*D15 -> 0 | L15: ARCOLOR V-O | M15: A6-Master Verde 4170
D16: 0.15 | E16: =C16*D16 -> 0 | G16: =F16*0.15 -> 0 | H16: =G16*D16 -> 0 | L16: BERMA | M16: B7-Master Rojo 100319
D17: 0.15 | E17: =C17*D17 -> 0 | G17: =F17*0.15 -> 0 | H17: =G17*D17 -> 0 | L17: YUTE | M17: A14- Master Yute 4101
D18: 0.15 | E18: =C18*D18 -> 0 | G18: =F18*0.15 -> 0 | H18: =G18*D18 -> 0 | L18: ARCOLOR | M18: A9-Master naranja 7363
D19: 0.15 | E19: =C19*D19 -> 0 | G19: =F19*0.15 -> 0 | H19: =G19*D19 -> 0
D20: 0.15 | E20: =C20*D20 -> 0 | G20: =F20*0.08 -> 0 | H20: =G20*D20 -> 0
D21: 0.15 | E21: =C21*D21 -> 0 | G21: =F21*0.08 -> 0 | H21: =G21*D21 -> 0
D22: 0.15 | E22: =C22*D22 -> 0 | G22: =F22*0.08 -> 0 | H22: =G22*D22 -> 0
D23: 0.15 | E23: =C23*D23 -> 0 | G23: =F23*0.08 -> 0 | H23: =G23*D23 -> 0
D24: 0.15 | E24: =C24*D24 -> 0 | G24: =F24*0.08 -> 0 | H24: =G24*D24 -> 0
D25: 0.15 | E25: =C25*D25 -> 0 | G25: =F25*0.08 -> 0 | H25: =G25*D25 -> 0
D26: 0.15 | E26: =C26*D26 -> 0 | G26: =F26*0.08 -> 0 | H26: =G26*D26 -> 0
C27: =SUM(C7:C26) -> 222 | D27: 0.15 | E27: =SUM(E7:E26) -> 33.17 | F27: =SUM(F5:F26) -> 0 | G27: =SUM(G5:G26) -> 0 | H27: =G27*D27 -> 0
E28: bolsas en stock | F28: =C27-F27 -> 222 | G28: Kg en stock | H28: =SUM(E6+E27-G27) -> 33.17
B31: B3-Master Blanco
B32: fecha | C32: cantidad armada B | D32: peso bolsa al 21/3/2025 | E32: peso por bolsa | F32: cantidad entregada por día | G32: peso
B33: bolsa abierta | G33: =F33*0.08 -> 0 | H33: =G33*D33 -> 0
D34: 0.15 | E34: 0 | G34: =F34*0.08 -> 0 | H34: =G34*D34 -> 0
D35: 0.15 | E35: =C35*D35 -> 0 | G35: =F35*0.08 -> 0 | H35: =G35*D35 -> 0
D36: 0.15 | E36: =C36*D36 -> 0 | G36: =F36*0.08 -> 0 | H36: =G36*D36 -> 0
D37: 0.15 | E37: =C37*D37 -> 0 | G37: =F37*0.08 -> 0 | H37: =G37*D37 -> 0
D38: 0.15 | E38: =C38*D38 -> 0 | G38: =F38*0.08 -> 0 | H38: =G38*D38 -> 0
D39: 0.15 | E39: =C39*D39 -> 0 | G39: =F39*0.08 -> 0 | H39: =G39*D39 -> 0
D40: 0.15 | E40: =C40*D40 -> 0 | G40: =F40*0.1 -> 0 | H40: =G40*D40 -> 0
D41: 0.15 | E41: =C41*D41 -> 0 | G41: =F41*0.08 -> 0 | H41: =G41*D41 -> 0
D42: 0.15 | E42: =C42*D42 -> 0 | G42: =F42*0.1 -> 0 | H42: =G42*D42 -> 0
D43: 0.15 | E43: =C43*D43 -> 0 | G43: =F43*0.1 -> 0 | H43: =G43*D43 -> 0
D44: 0.15 | E44: =C44*D44 -> 0 | G44: =F44*0.08 -> 0 | H44: =G44*D44 -> 0
...

Sheet BOLSONES 
B3: Canasto o bolsa | E3: 400- molienda de pisos (prueba)
B4: fecha | C4: tipo y n° | D4: peso | E4: lote | F4: fecha | G4: canasto N° | H4: Peso inicial | I4: Entradas | J4: Salidas | K4: TOTAL | L4: estado
F5: 46150 | K5: 270.18 | L5: abierto
B10: TOTAL BOSAS Y CANASTOS | D10: =SUM(D5:D9) -> 0 | G10: subtotales | H10: =SUM(H5:H9) -> 0 | I10: =SUM(I5:I9) -> 0 | J10: =SUM(J5:J9) -> 0 | K10: =SUM(K5:K9) -> 270.18
F11: PESO TOTAL BOLSON MAS CANASTOS | K11: =K10+D10 -> 270.18
B16: Canasto o bolsa | E16: 401- molienda p.rejillas (c-31)
B17: fecha | C17: tipo y n° | D17: peso | E17: lote | F17: fecha | G17: canasto N° | H17: Peso inicial | I17: Entradas | J17: Salidas | K17: TOTAL | L17: estado
F18: 46155 | H18: 47.2 | K18: 47.2 | L18: abierto
F19: 46226 | I19: 175.4
B23: TOTAL BOSAS Y CANASTOS | D23: =SUM(D18:D22) -> 0 | G23: subtotales | H23: =SUM(H18:H22) -> 47.2 | I23: =SUM(I18:I22) -> 175.4 | J23: =SUM(J18:J22) -> 0 | K23: =SUM(K18:K22) -> 47.2
F24: PESO TOTAL BOLSON MAS CANASTOS | K24: =SUM(I23+H18-J23) -> 222.6
B29: Canasto o bolsa | E29: 410-Molienda P- ciego c03+c19
B30: fecha | C30: tipo y n° | D30: peso | E30: lote | F30: fecha | G30: canasto N° | H30: Peso inicial | I30: Entradas | J30: Salidas | K30: TOTAL | L30: estado
B31: 46231 | C31: tacho | D31: 15.6
C32: tacho | D32: 19.2
C33: tacho | D33: 18.4
C34: tacho | D34: 19.2
C35: tacho | D35: 8.6
C36: tacho | D36: 16.2
C37: tacho | D37: 13.8
C38: tacho | D38: 15.2
C39: tacho | D39: 11.6
C40: tacho | D40: 12.4
B41: TOTAL BOSAS Y CANASTOS | D41: =SUM(D31:D40) -> 150.2 | G41: subtotales | H41: =SUM(H31:H40) -> 0 | I41: =SUM(I31:I40) -> 0 | J41: =SUM(J31:J40) -> 0 | K41: =SUM(K31:K40) -> 0
F42: PESO TOTAL BOLSON MAS CANASTOS | K42: =K41+D41 -> 150.2

Sheet borrador 
B4: Canasto o bolsa | E4: 115-Molienda Polipropieleno de primera
B5: fecha | C5: tipo y n° | D5: peso | E5: lote | F5: fecha | G5: canasto N° | H5: Peso inicial | I5: Entradas | J5: Salidas | K5: TOTAL | L5: estado
E6: 1 | K6: 257.6 | L6: cerrado
E7: 2 | K7: 488.305 | L7: cerrado
E8: 3 | K8: 370.4 | L8: cerrado
E9: 4 | K9: 468 | L9: cerrado
E10: 5 | K10: 746.2 | L10: cerrado
E11: 6 | K11: 314 | L11: cerrado
E12: 7 | K12: 221 | L12: cerrado
E13: 8 | K13: 297.84 | L13: cerrado
E14: 9 | K14: 316 | L14: cerrado
E15: 10 | H15: 194.895 | K15: =H15+I24-J24 -> 194.895
B24: TOTAL BOSAS Y CANASTOS | D24: =SUM(D6:D23) -> 0 | G24: subtotales | H24: =SUM(H15:H23) -> 194.895 | I24: =SUM(I6:I23) -> 0 | J24: =SUM(J15:J23) -> 0 | K24: =SUM(K6:K23) -> 3674.24
F25: PESO TOTAL BOLSON MAS CANASTOS | K25: =K24+D24 -> 3674.24 | M25: 3676.345
B29: Canasto o bolsa | E29: 124- Molienda Acetal de primera
B30: fecha | C30: tipo y n° | D30: peso | E30: lote | F30: fecha | G30: canasto N° | H30: Peso inicial | I30: Entradas | J30: Salidas | K30: TOTAL bolsones | L30: estado
E31: BOLSON 8 | F31: 45817 | H31: 754.625 | K31: =H31+I41-J41 -> 754.625
B32: 45959 | C32: b | D32: 18.4
C33: b | D33: 22.2
B41: TOTAL BOSAS Y CANASTOS | D41: =SUM(D31:D40) -> 40.6 | G41: subtotales | H41: =SUM(H31:H40) -> 754.625 | I41: =SUM(I31:I40) -> 0 | J41: =SUM(J31:J40) -> 0 | K41: =SUM(K31:K40) -> 754.625
F42: PESO TOTAL BOLSON MAS CANASTOS | K42: =K41+D41 -> 795.225
B44: Canasto o bolsa | E44: 117-Molienda Polipropileno con Fibra
B45: fecha | C45: tipo y n° | D45: peso | E45: lote o bolson | F45: fecha | G45: canasto N° | H45: Peso inicial | I45: Entradas | J45: Salidas | K45: PESO BOLSON | L45: estado
C46: c | D46: 16.315 | E46: 1 | H46: 405.6 | K46: =H46+I56-J56 -> 459.2
C47: c | D47: 23.51 | F47: 45817 | G47: 1 | I47: 17.2
C48: c | D48: 25 | F48: 45818 | G48: 1 | I48: 18.8
C49: c | D49: 22.31 | F49: 45819 | G49: 1 | I49: 17.6
C50: b | D50: 13.92
B51: 45952 | C51: b | D51: 15.2
B52: 45959 | C52: b | D52: 12.2
B53: 45959 | C53: b | D53: 8.2
B56: TOTAL BOSAS Y CANASTOS | D56: =SUM(D46:D55) -> 136.655 | G56: subtotales | H56: =SUM(H46:H55) -> 405.6 | I56: =SUM(I46:I55) -> 53.6 | J56: =SUM(J46:J55) -> 0 | K56: =SUM(K46:K55) -> 459.2
F57: PESO TOTAL BOLSON MAS CANASTOS | K57: =K56+D56 -> 595.855
B61: Canasto o bolsa | E61: 123- Molienda acetal negro
B62: fecha | C62: tipo y n° | D62: peso | E62: lote o bolson | F62: fecha | G62: canasto N° | H62: Peso inicial | I62: Entradas | J62: Salidas | K62: TOTAL bolsones | L62: estado
E63: 1 | H63: 632.8 | K63: =H63+I73-J73 -> 632.8
B73: TOTAL BOSAS Y CANASTOS | D73: =SUM(D63:D72) -> 0 | G73: subtotales | H73: =SUM(H63:H72) -> 632.8 | I73: =SUM(I63:I72) -> 0 | J73: =SUM(J63:J72) -> 0 | K73: =SUM(K63:K72) -> 632.8
F74: PESO TOTAL BOLSON MAS CANASTOS | K74: =K73+D73 -> 632.8
B77: Canasto o bolsa | E77: M157 MOLIENDA PVC CONTAMINADO
B78: fecha | C78: tipo y n° | D78: peso | E78: lote o bolson | F78: fecha | G78: canasto N° | H78: Peso inicial | I78: Entradas | J78: Salidas | K78: TOTAL bolsones | L78: estado
...

Sheet DATOS DE LA COMPRA 
B4: Daniela- Sabrina 28/04/2025
B5: FECHA | C5: MATERIAL VIRGEN | D5: Codigo del material del proveedor | E5: Kg | F5: PROVEEDOR | G5: N° DE ORDEN DE COMPRA CP | H5: REMITO | I5: OBSERVACIONES | J5: PARTIDA O LOTE | K5: CERTIFICADO DE CALIDAD | L5: RECIBIDO POR | M5: Se efectuo control de calidad Fecha | N5: laboratorio fecha | O5: FICHA TECNICA
B6: 46149 | C6: 31-COPOLIMERO 2240 P | D6: 2240P | E6: 1000 | F6: INDARNYL | G6: 0176/2026 | H6: 800012499 | I6: - | J6: si | K6: 67770 | L6: DANIELA | M6: 46149
B7: 46156 | C7: 24-Master negro 951 | D7: 951 | E7: 50 | F7: BERMA | G7: 055/2026D | H7: 69964 | J7: - | K7: L1664F270426 | L7: DANIELA | M7: 46156
B8: 46199 | C8: 38-compuesto PE AD SN | E8: 25 | F8: INDARNYL | H8: 800013005 | J8: SKP00004 | K8: 177 | L8: daniela | M8: 46199
B9: 46199 | C9: 3-Polipropileno COPOLIMERO COD:2630PC | D9: 2630pc | E9: 500 | F9: INDARNYL | G9: 0186/2026 | H9: 800012994 | J9: PC000003 | K9: 68233 | L9: daniela | M9: 46199
B10: 46199 | C10: 31-COPOLIMERO 2240 P | D10: 2240p | E10: 1000 | F10: INDARNYL | G10: 0186/2026 | H10: 800012994 | J10: PC000002 | K10: 68082 | L10: DANIELA | M10: 46199
B11: 46199 | C11: 39-Polipropileno homopolimero esencia | D11: material de prueba | E11: 25
B12: 46199 | C12: 40-polipropileno copolimero kunlun | D12: material de prueba | E12: 25
B13: 46199 | C13: 41-polipropileno copolimero sinopec | D13: material de prueba | E13: 25
B14: 46202 | C14: 19- PLASTOMER | D14: exact5371 | E14: 500 | F14: simko | G14: 0058/2026 | H14: 1021-00056192 | J14: 38376476 | K14: simko007 | L14: Eduardo Gonzalez | M14: 46202
B15: 46204 | C15: B1-Master Gris Oscuro 105808 | D15: 105808 | E15: 5 | F15: BERMA
B16: 46204 | C16: B10-Master Gris Oscuro nor 108900 (gris claro catalogo) | D16: 108900 | E16: 5 | F16: BERMA
B17: 46209 | C17: 38-compuesto PE AD SN | E17: 75 | F17: INDARNYL | G17: 0191/2026 | H17: 800013110 | J17: 177 | K17: pc000010 | L17: daniela
B18: 46209 | C18: 38-compuesto PE AD SN | E18: 25 | F18: INDARNYL | G18: 0191/2026 | H18: 800013110 | J18: 128 | K18: pc000009 | L18: daniela
B19: 46209 | C19: 31-COPOLIMERO 2240 P | D19: 2240p | E19: 1000 | F19: INDARNYL | G19: 0191/2026 | H19: 800013109 | J19: 68082 | K19: pc000008 | L19: daniela
B20: 46211 | C20: B1-Master Gris Oscuro 105808 | D20: 105808 | E20: 25 | F20: BERMA | L20: Alejandro R.
B21: 46219 | C21: A3- Master blanco 7500 | D21: 7500 | E21: 5 | F21: ARCOLOR | L21: DANIELA
B22: 46219 | C22: A13- master obispo | D22: 3119 | E22: 5 | F22: ARCOLOR | L22: DANIELA
B23: 46219 | C23: A9-Master naranja 7363 | D23: 7363 | E23: 5 | F23: ARCOLOR | L23: DANIELA
B24: 46219 | C24: A4- Master Azul 3351 | D24: 3351 | E24: 5 | F24: ARCOLOR | L24: DANIELA
B25: 46219 | C25: A6-Master Verde 4170 | D25: 4170 | E25: 4.99 | F25: ARCOLOR | L25: DANIELA
B26: 46223 | C26: 31-COPOLIMERO 2240 P | D26: 2240P | E26: 1500 | F26: INDARNYL | G26: 0193/2026 | H26: 80013285 | J26: 68082 | K26: PC000011 | L26: daniela
B27: 46226 | C27: 31-COPOLIMERO 2240 P | D27: 2240p | E27: 6000 | F27: INDARNYL | G27: 0195/2026 | H27: 80013326 | J27: 68082 | K27: pc000013 | L27: daniela
B28: 46239 | C28: 3-Polipropileno COPOLIMERO COD:2630PC | D28: 2630pc | E28: 4000 | F28: INDARNYL | G28: 0198/2026 | H28: 800013470 | J28: 68453 | K28: pc000014 | L28: daniela
B29: 46239 | C29: B1-Master Gris Oscuro 105808 | D29: 105808 | E29: 35 | F29: BERMA | G29: 0197/2026-199/2026 | H29: 011-00046271 | L29: daniela
B30: 46239 | C30: 24-Master negro 951 | D30: 951 | E30: 50 | F30: BERMA | G30: 197/2026 | H30: 011-00046271 | L30: daniela
B31: 46239 | C31: B7-Master Rojo 100319 | D31: 100319 | E31: 5 | F31: BERMA | G31: 197/2026 | H31: 011-00046271 | L31: daniela
B32: 46244 | C32: A5- Master Amarillo 7228 | D32: 7228 | E32: 5 | F32: ARCOLOR | G32: 064/2026d | H32: 0104-000144887 | L32: daniela
B33: 46244 | C33: A14- Master Yute 4101 | D33: 4101 | E33: 5 | F33: ARCOLOR | G33: 064/2026d | H33: 0104-000144887 | L33: daniela
B34: 46244 | C34: A4- Master Azul 3351 | D34: 3351 | E34: 25 | F34: ARCOLOR | G34: 0066/2026d | H34: 0104-00014496 | L34: daniela

Sheet Hoja1
